<?xml version="1.0" ?>
<!-- =================================================================================== -->
<!-- |    This document was autogenerated by xacro from /home/jojo99/moveit_ws/src/two_arm_description/urdf/two_arm.xacro | -->
<!-- |    EDITING THIS FILE BY HAND IS NOT RECOMMENDED                                 | -->
<!-- =================================================================================== -->
<robot name="two_arm">
    <material name="silver">
        <color rgba="0.700 0.700 0.700 1.000" />
    </material>
    <transmission name="Revolute_5_tran">
        <type>transmission_interface/SimpleTransmission</type>
        <joint name="Revolute_5">
            <hardwareInterface>hardware_interface/EffortJointInterface</hardwareInterface>
        </joint>
        <actuator name="Revolute_5_actr">
            <hardwareInterface>hardware_interface/EffortJointInterface</hardwareInterface>
            <mechanicalReduction>1</mechanicalReduction>
        </actuator>
    </transmission>
    <transmission name="Revolute_12_tran">
        <type>transmission_interface/SimpleTransmission</type>
        <joint name="Revolute_12">
            <hardwareInterface>hardware_interface/EffortJointInterface</hardwareInterface>
        </joint>
        <actuator name="Revolute_12_actr">
            <hardwareInterface>hardware_interface/EffortJointInterface</hardwareInterface>
            <mechanicalReduction>1</mechanicalReduction>
        </actuator>
    </transmission>
    <transmission name="Revolute_13_tran">
        <type>transmission_interface/SimpleTransmission</type>
        <joint name="Revolute_13">
            <hardwareInterface>hardware_interface/EffortJointInterface</hardwareInterface>
        </joint>
        <actuator name="Revolute_13_actr">
            <hardwareInterface>hardware_interface/EffortJointInterface</hardwareInterface>
            <mechanicalReduction>1</mechanicalReduction>
        </actuator>
    </transmission>
    <transmission name="Revolute_23_tran">
        <type>transmission_interface/SimpleTransmission</type>
        <joint name="Revolute_23">
            <hardwareInterface>hardware_interface/EffortJointInterface</hardwareInterface>
        </joint>
        <actuator name="Revolute_23_actr">
            <hardwareInterface>hardware_interface/EffortJointInterface</hardwareInterface>
            <mechanicalReduction>1</mechanicalReduction>
        </actuator>
    </transmission>
    <transmission name="Revolute_26_tran">
        <type>transmission_interface/SimpleTransmission</type>
        <joint name="Revolute_26">
            <hardwareInterface>hardware_interface/EffortJointInterface</hardwareInterface>
        </joint>
        <actuator name="Revolute_26_actr">
            <hardwareInterface>hardware_interface/EffortJointInterface</hardwareInterface>
            <mechanicalReduction>1</mechanicalReduction>
        </actuator>
    </transmission>
    <transmission name="Revolute_30_tran">
        <type>transmission_interface/SimpleTransmission</type>
        <joint name="Revolute_30">
            <hardwareInterface>hardware_interface/EffortJointInterface</hardwareInterface>
        </joint>
        <actuator name="Revolute_30_actr">
            <hardwareInterface>hardware_interface/EffortJointInterface</hardwareInterface>
            <mechanicalReduction>1</mechanicalReduction>
        </actuator>
    </transmission>
    <transmission name="Revolute_33_tran">
        <type>transmission_interface/SimpleTransmission</type>
        <joint name="Revolute_33">
            <hardwareInterface>hardware_interface/EffortJointInterface</hardwareInterface>
        </joint>
        <actuator name="Revolute_33_actr">
            <hardwareInterface>hardware_interface/EffortJointInterface</hardwareInterface>
            <mechanicalReduction>1</mechanicalReduction>
        </actuator>
    </transmission>
    <transmission name="Revolute_35_tran">
        <type>transmission_interface/SimpleTransmission</type>
        <joint name="Revolute_35">
            <hardwareInterface>hardware_interface/EffortJointInterface</hardwareInterface>
        </joint>
        <actuator name="Revolute_35_actr">
            <hardwareInterface>hardware_interface/EffortJointInterface</hardwareInterface>
            <mechanicalReduction>1</mechanicalReduction>
        </actuator>
    </transmission>
    <transmission name="Revolute_41_tran">
        <type>transmission_interface/SimpleTransmission</type>
        <joint name="Revolute_41">
            <hardwareInterface>hardware_interface/EffortJointInterface</hardwareInterface>
        </joint>
        <actuator name="Revolute_41_actr">
            <hardwareInterface>hardware_interface/EffortJointInterface</hardwareInterface>
            <mechanicalReduction>1</mechanicalReduction>
        </actuator>
    </transmission>
    <transmission name="Revolute_43_tran">
        <type>transmission_interface/SimpleTransmission</type>
        <joint name="Revolute_43">
            <hardwareInterface>hardware_interface/EffortJointInterface</hardwareInterface>
        </joint>
        <actuator name="Revolute_43_actr">
            <hardwareInterface>hardware_interface/EffortJointInterface</hardwareInterface>
            <mechanicalReduction>1</mechanicalReduction>
        </actuator>
    </transmission>
    <gazebo>
        <plugin filename="libgazebo_ros_control.so" name="control" />
        <plugin name="gazebo_ros_control" filename="libgazebo_ros_control.so">
            <robotNamespace>/</robotNamespace>
        </plugin>
    </gazebo>
    <gazebo reference="base_link">
        <material>Gazebo/Silver</material>
        <mu1>0.2</mu1>
        <mu2>0.2</mu2>
        <selfCollide>true</selfCollide>
        <gravity>true</gravity>
    </gazebo>
    <gazebo reference="ROUE_MX106T_v1_1">
        <material>Gazebo/Silver</material>
        <mu1>0.2</mu1>
        <mu2>0.2</mu2>
        <selfCollide>true</selfCollide>
    </gazebo>
    <gazebo reference="bearing_v1_1">
        <material>Gazebo/Silver</material>
        <mu1>0.2</mu1>
        <mu2>0.2</mu2>
        <selfCollide>true</selfCollide>
    </gazebo>
    <gazebo reference="joint_pivot_seat_v1_1">
        <material>Gazebo/Silver</material>
        <mu1>0.2</mu1>
        <mu2>0.2</mu2>
        <selfCollide>true</selfCollide>
    </gazebo>
    <gazebo reference="s_s_link_v1_2">
        <material>Gazebo/Silver</material>
        <mu1>0.2</mu1>
        <mu2>0.2</mu2>
        <selfCollide>true</selfCollide>
    </gazebo>
    <gazebo reference="motorwithROUE_v4_2">
        <material>Gazebo/Silver</material>
        <mu1>0.2</mu1>
        <mu2>0.2</mu2>
        <selfCollide>true</selfCollide>
    </gazebo>
    <gazebo reference="motorwithROUE_v4_1">
        <material>Gazebo/Silver</material>
        <mu1>0.2</mu1>
        <mu2>0.2</mu2>
        <selfCollide>true</selfCollide>
    </gazebo>
    <gazebo reference="uparm1_v1_1">
        <material>Gazebo/Silver</material>
        <mu1>0.2</mu1>
        <mu2>0.2</mu2>
        <selfCollide>true</selfCollide>
    </gazebo>
    <gazebo reference="ROUE_MX106T_v1_2">
        <material>Gazebo/Silver</material>
        <mu1>0.2</mu1>
        <mu2>0.2</mu2>
        <selfCollide>true</selfCollide>
    </gazebo>
    <gazebo reference="uparm_out_v1_1">
        <material>Gazebo/Silver</material>
        <mu1>0.2</mu1>
        <mu2>0.2</mu2>
        <selfCollide>true</selfCollide>
    </gazebo>
    <gazebo reference="uparm2_v1_1">
        <material>Gazebo/Silver</material>
        <mu1>0.2</mu1>
        <mu2>0.2</mu2>
        <selfCollide>true</selfCollide>
    </gazebo>
    <gazebo reference="uparm_in_v1_1">
        <material>Gazebo/Silver</material>
        <mu1>0.2</mu1>
        <mu2>0.2</mu2>
        <selfCollide>true</selfCollide>
    </gazebo>
    <gazebo reference="uparm3_v1_1">
        <material>Gazebo/Silver</material>
        <mu1>0.2</mu1>
        <mu2>0.2</mu2>
        <selfCollide>true</selfCollide>
    </gazebo>
    <gazebo reference="motorwithROUE_v4_3">
        <material>Gazebo/Silver</material>
        <mu1>0.2</mu1>
        <mu2>0.2</mu2>
        <selfCollide>true</selfCollide>
    </gazebo>
    <gazebo reference="front_arm1_v1_1">
        <material>Gazebo/Silver</material>
        <mu1>0.2</mu1>
        <mu2>0.2</mu2>
        <selfCollide>true</selfCollide>
    </gazebo>
    <gazebo reference="motorwithROUE_v4_4">
        <material>Gazebo/Silver</material>
        <mu1>0.2</mu1>
        <mu2>0.2</mu2>
        <selfCollide>true</selfCollide>
    </gazebo>
    <gazebo reference="s_s_link2_v1_1">
        <material>Gazebo/Silver</material>
        <mu1>0.2</mu1>
        <mu2>0.2</mu2>
        <selfCollide>true</selfCollide>
    </gazebo>
    <gazebo reference="motorwithROUE_v4_5">
        <material>Gazebo/Silver</material>
        <mu1>0.2</mu1>
        <mu2>0.2</mu2>
        <selfCollide>true</selfCollide>
    </gazebo>
    <gazebo reference="ROUE_MX106T_v1_3">
        <material>Gazebo/Silver</material>
        <mu1>0.2</mu1>
        <mu2>0.2</mu2>
        <selfCollide>true</selfCollide>
    </gazebo>
    <gazebo reference="bearing_v1_2">
        <material>Gazebo/Silver</material>
        <mu1>0.2</mu1>
        <mu2>0.2</mu2>
        <selfCollide>true</selfCollide>
    </gazebo>
    <gazebo reference="joint_pivot_seat_v1_2">
        <material>Gazebo/Silver</material>
        <mu1>0.2</mu1>
        <mu2>0.2</mu2>
        <selfCollide>true</selfCollide>
    </gazebo>
    <gazebo reference="s_s_link_v1_1">
        <material>Gazebo/Silver</material>
        <mu1>0.2</mu1>
        <mu2>0.2</mu2>
        <selfCollide>true</selfCollide>
    </gazebo>
    <gazebo reference="motorwithROUE_v4_6">
        <material>Gazebo/Silver</material>
        <mu1>0.2</mu1>
        <mu2>0.2</mu2>
        <selfCollide>true</selfCollide>
    </gazebo>
    <gazebo reference="uparm1_v1_2">
        <material>Gazebo/Silver</material>
        <mu1>0.2</mu1>
        <mu2>0.2</mu2>
        <selfCollide>true</selfCollide>
    </gazebo>
    <gazebo reference="uparm_out_v1_2">
        <material>Gazebo/Silver</material>
        <mu1>0.2</mu1>
        <mu2>0.2</mu2>
        <selfCollide>true</selfCollide>
    </gazebo>
    <gazebo reference="uparm2_v1_2">
        <material>Gazebo/Silver</material>
        <mu1>0.2</mu1>
        <mu2>0.2</mu2>
        <selfCollide>true</selfCollide>
    </gazebo>
    <gazebo reference="uparm_in_v1_2">
        <material>Gazebo/Silver</material>
        <mu1>0.2</mu1>
        <mu2>0.2</mu2>
        <selfCollide>true</selfCollide>
    </gazebo>
    <gazebo reference="uparm3_v1_2">
        <material>Gazebo/Silver</material>
        <mu1>0.2</mu1>
        <mu2>0.2</mu2>
        <selfCollide>true</selfCollide>
    </gazebo>
    <gazebo reference="motorwithROUE_v4_8">
        <material>Gazebo/Silver</material>
        <mu1>0.2</mu1>
        <mu2>0.2</mu2>
        <selfCollide>true</selfCollide>
    </gazebo>
    <gazebo reference="front_arm1_v1_2">
        <material>Gazebo/Silver</material>
        <mu1>0.2</mu1>
        <mu2>0.2</mu2>
        <selfCollide>true</selfCollide>
    </gazebo>
    <gazebo reference="motorwithROUE_v4_9">
        <material>Gazebo/Silver</material>
        <mu1>0.2</mu1>
        <mu2>0.2</mu2>
        <selfCollide>true</selfCollide>
    </gazebo>
    <gazebo reference="s_s_link2_v1_2">
        <material>Gazebo/Silver</material>
        <mu1>0.2</mu1>
        <mu2>0.2</mu2>
        <selfCollide>true</selfCollide>
    </gazebo>
    <gazebo reference="motorwithROUE_v4_10">
        <material>Gazebo/Silver</material>
        <mu1>0.2</mu1>
        <mu2>0.2</mu2>
        <selfCollide>true</selfCollide>
    </gazebo>
    <gazebo reference="MX-106T_v1_1">
        <material>Gazebo/Silver</material>
        <mu1>0.2</mu1>
        <mu2>0.2</mu2>
        <selfCollide>true</selfCollide>
    </gazebo>
    <gazebo reference="MX-106T_v1_2">
        <material>Gazebo/Silver</material>
        <mu1>0.2</mu1>
        <mu2>0.2</mu2>
        <selfCollide>true</selfCollide>
    </gazebo>
    <gazebo reference="ROUE_MX106T_v1_4">
        <material>Gazebo/Silver</material>
        <mu1>0.2</mu1>
        <mu2>0.2</mu2>
        <selfCollide>true</selfCollide>
    </gazebo>
    <gazebo reference="motorwithROUE_v4_7">
        <material>Gazebo/Silver</material>
        <mu1>0.2</mu1>
        <mu2>0.2</mu2>
        <selfCollide>true</selfCollide>
    </gazebo>
    <gazebo reference="front_arm2_v1_1">
        <material>Gazebo/Silver</material>
        <mu1>0.2</mu1>
        <mu2>0.2</mu2>
        <selfCollide>true</selfCollide>
    </gazebo>
    <gazebo reference="front_arm2_v1_2">
        <material>Gazebo/Silver</material>
        <mu1>0.2</mu1>
        <mu2>0.2</mu2>
        <selfCollide>true</selfCollide>
    </gazebo>
    <link name="world" />
    <link name="base_link">
        <inertial>
            <origin rpy="0 0 0" xyz="-0.07413266559584324 -0.3000000000000007 0.24507468584151412" />
            <mass value="0.38748537056758814" />
            <inertia ixx="0.0081" ixy="0.0" ixz="-0.000221" iyy="0.0063" iyz="-0.0" izz="0.001982" />
        </inertial>
        <visual>
            <origin rpy="0 0 0" xyz="0 0 0" />
            <geometry>
                <mesh filename="package://two_arm_description/meshes/base_link.stl" scale="1 1 1" />
            </geometry>
            <material name="silver" />
        </visual>
        <collision>
            <origin rpy="0 0 0" xyz="0 0 0" />
            <geometry>
                <mesh filename="package://two_arm_description/meshes/base_link.stl" scale="0.001 0.001 0.001" />
            </geometry>
        </collision>
    </link>
    <link name="ROUE_MX106T_v1_1">
        <inertial>
            <origin rpy="0 0 0" xyz="0.001900450853613747 1.277943341149168e-07 -2.7700064464397656e-14" />
            <mass value="0.0014398491546385346" />
            <inertia ixx="0.0" ixy="-0.0" ixz="-0.0" iyy="0.0" iyz="0.0" izz="0.0" />
        </inertial>
        <visual>
            <origin rpy="0 0 0" xyz="0.051095 0.431 -0.37525" />
            <geometry>
                <mesh filename="package://two_arm_description/meshes/ROUE_MX106T_v1_1.stl" scale="1 1 1" />
            </geometry>
            <material name="silver" />
        </visual>
        <collision>
            <origin rpy="0 0 0" xyz="0.051095 0.431 -0.37525" />
            <geometry>
                <mesh filename="package://two_arm_description/meshes/ROUE_MX106T_v1_1.stl" scale="0.001 0.001 0.001" />
            </geometry>
        </collision>
    </link>
    <link name="bearing_v1_1">
        <inertial>
            <origin rpy="0 0 0" xyz="0.009024717492524488 -1.7550405573274475e-12 -5.551115123125783e-17" />
            <mass value="0.04321868842161265" />
            <inertia ixx="1.6e-05" ixy="0.0" ixz="0.0" iyy="1e-05" iyz="0.0" izz="9e-06" />
        </inertial>
        <visual>
            <origin rpy="0 0 0" xyz="0.045795 0.431 -0.37525" />
            <geometry>
                <mesh filename="package://two_arm_description/meshes/bearing_v1_1.stl" scale="1 1 1" />
            </geometry>
            <material name="silver" />
        </visual>
        <collision>
            <origin rpy="0 0 0" xyz="0.045795 0.431 -0.37525" />
            <geometry>
                <mesh filename="package://two_arm_description/meshes/bearing_v1_1.stl" scale="0.001 0.001 0.001" />
            </geometry>
        </collision>
    </link>
    <link name="joint_pivot_seat_v1_1">
        <inertial>
            <origin rpy="0 0 0" xyz="0.010686949814513444 -1.7440493493836584e-12 -4.107825191113079e-15" />
            <mass value="0.014233239752431062" />
            <inertia ixx="2.2e-05" ixy="0.0" ixz="-0.0" iyy="7e-06" iyz="6e-06" izz="2.1e-05" />
        </inertial>
        <visual>
            <origin rpy="0 0 0" xyz="0.025795 0.431 -0.37525" />
            <geometry>
                <mesh filename="package://two_arm_description/meshes/joint_pivot_seat_v1_1.stl" scale="1 1 1" />
            </geometry>
            <material name="silver" />
        </visual>
        <collision>
            <origin rpy="0 0 0" xyz="0.025795 0.431 -0.37525" />
            <geometry>
                <mesh filename="package://two_arm_description/meshes/joint_pivot_seat_v1_1.stl" scale="0.001 0.001 0.001" />
            </geometry>
        </collision>
    </link>
    <link name="s_s_link_v1_2">
        <inertial>
            <origin rpy="0 0 0" xyz="0.00837478100224047 -0.007236841973399466 -0.004865563577700627" />
            <mass value="0.001474300888156925" />
            <inertia ixx="0.0" ixy="0.0" ixz="0.0" iyy="0.0" iyz="-0.0" izz="0.0" />
        </inertial>
        <visual>
            <origin rpy="0 0 0" xyz="-0.037269 0.42882 -0.374787" />
            <geometry>
                <mesh filename="package://two_arm_description/meshes/s_s_link_v1_2.stl" scale="1 1 1" />
            </geometry>
            <material name="silver" />
        </visual>
        <collision>
            <origin rpy="0 0 0" xyz="-0.037269 0.42882 -0.374787" />
            <geometry>
                <mesh filename="package://two_arm_description/meshes/s_s_link_v1_2.stl" scale="0.001 0.001 0.001" />
            </geometry>
        </collision>
    </link>
    <link name="motorwithROUE_v4_2">
        <inertial>
            <origin rpy="0 0 0" xyz="-0.013329028009352414 -0.020152393924282364 -0.004132715651212704" />
            <mass value="0.08480439041253407" />
            <inertia ixx="2.6e-05" ixy="2e-06" ixz="5e-06" iyy="3.9e-05" iyz="-4e-06" izz="3e-05" />
        </inertial>
        <visual>
            <origin rpy="0 0 0" xyz="-0.037269 0.437214 -0.378034" />
            <geometry>
                <mesh filename="package://two_arm_description/meshes/motorwithROUE_v4_2.stl" scale="1 1 1" />
            </geometry>
            <material name="silver" />
        </visual>
        <collision>
            <origin rpy="0 0 0" xyz="-0.037269 0.437214 -0.378034" />
            <geometry>
                <mesh filename="package://two_arm_description/meshes/motorwithROUE_v4_2.stl" scale="0.001 0.001 0.001" />
            </geometry>
        </collision>
    </link>
    <link name="motorwithROUE_v4_1">
        <inertial>
            <origin rpy="0 0 0" xyz="0.01158371111642428 -0.02915425527179344 -0.00032880555253705923" />
            <mass value="0.08480439041253407" />
            <inertia ixx="3.1e-05" ixy="4e-06" ixz="8e-06" iyy="3.2e-05" iyz="-0.0" izz="3.2e-05" />
        </inertial>
        <visual>
            <origin rpy="0 0 0" xyz="-0.012305 0.387632 -0.358472" />
            <geometry>
                <mesh filename="package://two_arm_description/meshes/motorwithROUE_v4_1.stl" scale="1 1 1" />
            </geometry>
            <material name="silver" />
        </visual>
        <collision>
            <origin rpy="0 0 0" xyz="-0.012305 0.387632 -0.358472" />
            <geometry>
                <mesh filename="package://two_arm_description/meshes/motorwithROUE_v4_1.stl" scale="0.001 0.001 0.001" />
            </geometry>
        </collision>
    </link>
    <link name="uparm1_v1_1">
        <inertial>
            <origin rpy="0 0 0" xyz="0.020990843972701304 -0.015870993355479535 -0.017737281961678675" />
            <mass value="0.00664014891173441" />
            <inertia ixx="2e-06" ixy="0.0" ixz="1e-06" iyy="2e-06" iyz="0.0" izz="2e-06" />
        </inertial>
        <visual>
            <origin rpy="0 0 0" xyz="0.006467 0.460727 -0.365204" />
            <geometry>
                <mesh filename="package://two_arm_description/meshes/uparm1_v1_1.stl" scale="1 1 1" />
            </geometry>
            <material name="silver" />
        </visual>
        <collision>
            <origin rpy="0 0 0" xyz="0.006467 0.460727 -0.365204" />
            <geometry>
                <mesh filename="package://two_arm_description/meshes/uparm1_v1_1.stl" scale="0.001 0.001 0.001" />
            </geometry>
        </collision>
    </link>
    <link name="ROUE_MX106T_v1_2">
        <inertial>
            <origin rpy="0 0 0" xyz="0.0012971617445040051 0.0005005651439544123 0.001295033486768682" />
            <mass value="0.0014398491546385346" />
            <inertia ixx="0.0" ixy="0.0" ixz="0.0" iyy="0.0" iyz="0.0" izz="0.0" />
        </inertial>
        <visual>
            <origin rpy="0 0 0" xyz="-0.028211 0.447333 -0.399825" />
            <geometry>
                <mesh filename="package://two_arm_description/meshes/ROUE_MX106T_v1_2.stl" scale="1 1 1" />
            </geometry>
            <material name="silver" />
        </visual>
        <collision>
            <origin rpy="0 0 0" xyz="-0.028211 0.447333 -0.399825" />
            <geometry>
                <mesh filename="package://two_arm_description/meshes/ROUE_MX106T_v1_2.stl" scale="0.001 0.001 0.001" />
            </geometry>
        </collision>
    </link>
    <link name="uparm_out_v1_1">
        <inertial>
            <origin rpy="0 0 0" xyz="0.05289333423136254 -0.013971655671968453 -0.0006739816117338204" />
            <mass value="0.005528894316363056" />
            <inertia ixx="4e-06" ixy="2e-06" ixz="1e-06" iyy="7e-06" iyz="-2e-06" izz="6e-06" />
        </inertial>
        <visual>
            <origin rpy="0 0 0" xyz="-0.025574 0.509793 -0.344681" />
            <geometry>
                <mesh filename="package://two_arm_description/meshes/uparm_out_v1_1.stl" scale="1 1 1" />
            </geometry>
            <material name="silver" />
        </visual>
        <collision>
            <origin rpy="0 0 0" xyz="-0.025574 0.509793 -0.344681" />
            <geometry>
                <mesh filename="package://two_arm_description/meshes/uparm_out_v1_1.stl" scale="0.001 0.001 0.001" />
            </geometry>
        </collision>
    </link>
    <link name="uparm2_v1_1">
        <inertial>
            <origin rpy="0 0 0" xyz="0.01864568320104463 0.015525776764443944 -0.014588390344488056" />
            <mass value="0.004361377871447323" />
            <inertia ixx="1e-06" ixy="-0.0" ixz="0.0" iyy="1e-06" iyz="0.0" izz="1e-06" />
        </inertial>
        <visual>
            <origin rpy="0 0 0" xyz="-0.031844 0.513283 -0.341401" />
            <geometry>
                <mesh filename="package://two_arm_description/meshes/uparm2_v1_1.stl" scale="1 1 1" />
            </geometry>
            <material name="silver" />
        </visual>
        <collision>
            <origin rpy="0 0 0" xyz="-0.031844 0.513283 -0.341401" />
            <geometry>
                <mesh filename="package://two_arm_description/meshes/uparm2_v1_1.stl" scale="0.001 0.001 0.001" />
            </geometry>
        </collision>
    </link>
    <link name="uparm_in_v1_1">
        <inertial>
            <origin rpy="0 0 0" xyz="0.0298180351183487 0.0031142967661877408 0.014178859829912571" />
            <mass value="0.0032836847073492706" />
            <inertia ixx="1e-06" ixy="0.0" ixz="-0.0" iyy="2e-06" iyz="-1e-06" izz="2e-06" />
        </inertial>
        <visual>
            <origin rpy="0 0 0" xyz="-0.041187 0.473089 -0.316493" />
            <geometry>
                <mesh filename="package://two_arm_description/meshes/uparm_in_v1_1.stl" scale="1 1 1" />
            </geometry>
            <material name="silver" />
        </visual>
        <collision>
            <origin rpy="0 0 0" xyz="-0.041187 0.473089 -0.316493" />
            <geometry>
                <mesh filename="package://two_arm_description/meshes/uparm_in_v1_1.stl" scale="0.001 0.001 0.001" />
            </geometry>
        </collision>
    </link>
    <link name="uparm3_v1_1">
        <inertial>
            <origin rpy="0 0 0" xyz="0.005013426725472017 -0.03732985320716553 0.005452560041179388" />
            <mass value="0.002974291147078946" />
            <inertia ixx="1e-06" ixy="0.0" ixz="0.0" iyy="1e-06" iyz="0.0" izz="2e-06" />
        </inertial>
        <visual>
            <origin rpy="0 0 0" xyz="-0.071981 0.487835 -0.304249" />
            <geometry>
                <mesh filename="package://two_arm_description/meshes/uparm3_v1_1.stl" scale="1 1 1" />
            </geometry>
            <material name="silver" />
        </visual>
        <collision>
            <origin rpy="0 0 0" xyz="-0.071981 0.487835 -0.304249" />
            <geometry>
                <mesh filename="package://two_arm_description/meshes/uparm3_v1_1.stl" scale="0.001 0.001 0.001" />
            </geometry>
        </collision>
    </link>
    <link name="motorwithROUE_v4_3">
        <inertial>
            <origin rpy="0 0 0" xyz="0.025108313759364842 -0.021708849802870467 0.00785769306510492" />
            <mass value="0.08480439041253407" />
            <inertia ixx="2.8e-05" ixy="5e-06" ixz="3e-06" iyy="3.5e-05" iyz="-6e-06" izz="3.1e-05" />
        </inertial>
        <visual>
            <origin rpy="0 0 0" xyz="-0.075343 0.498889 -0.30083" />
            <geometry>
                <mesh filename="package://two_arm_description/meshes/motorwithROUE_v4_3.stl" scale="1 1 1" />
            </geometry>
            <material name="silver" />
        </visual>
        <collision>
            <origin rpy="0 0 0" xyz="-0.075343 0.498889 -0.30083" />
            <geometry>
                <mesh filename="package://two_arm_description/meshes/motorwithROUE_v4_3.stl" scale="0.001 0.001 0.001" />
            </geometry>
        </collision>
    </link>
    <link name="front_arm1_v1_1">
        <inertial>
            <origin rpy="0 0 0" xyz="0.04249418907763622 -0.004441762890337153 0.0017055017347186174" />
            <mass value="0.0207169446193885" />
            <inertia ixx="1.3e-05" ixy="-1e-06" ixz="-3e-06" iyy="1.6e-05" iyz="-1e-06" izz="1.3e-05" />
        </inertial>
        <visual>
            <origin rpy="0 0 0" xyz="-0.0928 0.535558 -0.281684" />
            <geometry>
                <mesh filename="package://two_arm_description/meshes/front_arm1_v1_1.stl" scale="1 1 1" />
            </geometry>
            <material name="silver" />
        </visual>
        <collision>
            <origin rpy="0 0 0" xyz="-0.0928 0.535558 -0.281684" />
            <geometry>
                <mesh filename="package://two_arm_description/meshes/front_arm1_v1_1.stl" scale="0.001 0.001 0.001" />
            </geometry>
        </collision>
    </link>
    <link name="motorwithROUE_v4_4">
        <inertial>
            <origin rpy="0 0 0" xyz="0.0061326193991840805 -0.023732162836644033 -0.00010947815243900205" />
            <mass value="0.08480439041253407" />
            <inertia ixx="2.9e-05" ixy="-0.0" ixz="-6e-06" iyy="3.6e-05" iyz="-6e-06" izz="3e-05" />
        </inertial>
        <visual>
            <origin rpy="0 0 0" xyz="-0.154059 0.543476 -0.265939" />
            <geometry>
                <mesh filename="package://two_arm_description/meshes/motorwithROUE_v4_4.stl" scale="1 1 1" />
            </geometry>
            <material name="silver" />
        </visual>
        <collision>
            <origin rpy="0 0 0" xyz="-0.154059 0.543476 -0.265939" />
            <geometry>
                <mesh filename="package://two_arm_description/meshes/motorwithROUE_v4_4.stl" scale="0.001 0.001 0.001" />
            </geometry>
        </collision>
    </link>
    <link name="s_s_link2_v1_1">
        <inertial>
            <origin rpy="0 0 0" xyz="0.0005622313716805161 -0.0004463659843791934 -0.0003912287588315466" />
            <mass value="0.0064776173686798945" />
            <inertia ixx="2e-06" ixy="-0.0" ixz="-0.0" iyy="2e-06" iyz="0.0" izz="2e-06" />
        </inertial>
        <visual>
            <origin rpy="0 0 0" xyz="-0.168341 0.586438 -0.241843" />
            <geometry>
                <mesh filename="package://two_arm_description/meshes/s_s_link2_v1_1.stl" scale="1 1 1" />
            </geometry>
            <material name="silver" />
        </visual>
        <collision>
            <origin rpy="0 0 0" xyz="-0.168341 0.586438 -0.241843" />
            <geometry>
                <mesh filename="package://two_arm_description/meshes/s_s_link2_v1_1.stl" scale="0.001 0.001 0.001" />
            </geometry>
        </collision>
    </link>
    <link name="motorwithROUE_v4_5">
        <inertial>
            <origin rpy="0 0 0" xyz="0.031989376408686404 -0.01989090182022435 0.001936033289041128" />
            <mass value="0.08480439041253407" />
            <inertia ixx="2.8e-05" ixy="5e-06" ixz="2e-06" iyy="3.4e-05" iyz="-7e-06" izz="3.3e-05" />
        </inertial>
        <visual>
            <origin rpy="0 0 0" xyz="-0.159884 0.585565 -0.222815" />
            <geometry>
                <mesh filename="package://two_arm_description/meshes/motorwithROUE_v4_5.stl" scale="1 1 1" />
            </geometry>
            <material name="silver" />
        </visual>
        <collision>
            <origin rpy="0 0 0" xyz="-0.159884 0.585565 -0.222815" />
            <geometry>
                <mesh filename="package://two_arm_description/meshes/motorwithROUE_v4_5.stl" scale="0.001 0.001 0.001" />
            </geometry>
        </collision>
    </link>
    <link name="ROUE_MX106T_v1_3">
        <inertial>
            <origin rpy="0 0 0" xyz="0.001900450853501899 1.2779468067103394e-07 -2.7644553313166398e-14" />
            <mass value="0.0014398491546385346" />
            <inertia ixx="0.0" ixy="-0.0" ixz="-0.0" iyy="0.0" iyz="0.0" izz="0.0" />
        </inertial>
        <visual>
            <origin rpy="0 0 0" xyz="0.048095 0.17 -0.37525" />
            <geometry>
                <mesh filename="package://two_arm_description/meshes/ROUE_MX106T_v1_3.stl" scale="1 1 1" />
            </geometry>
            <material name="silver" />
        </visual>
        <collision>
            <origin rpy="0 0 0" xyz="0.048095 0.17 -0.37525" />
            <geometry>
                <mesh filename="package://two_arm_description/meshes/ROUE_MX106T_v1_3.stl" scale="0.001 0.001 0.001" />
            </geometry>
        </collision>
    </link>
    <link name="bearing_v1_2">
        <inertial>
            <origin rpy="0 0 0" xyz="0.009024717492449652 -1.4084844401907048e-12 0.0" />
            <mass value="0.04321868842161265" />
            <inertia ixx="1.6e-05" ixy="0.0" ixz="0.0" iyy="1e-05" iyz="0.0" izz="9e-06" />
        </inertial>
        <visual>
            <origin rpy="0 0 0" xyz="0.042795 0.17 -0.37525" />
            <geometry>
                <mesh filename="package://two_arm_description/meshes/bearing_v1_2.stl" scale="1 1 1" />
            </geometry>
            <material name="silver" />
        </visual>
        <collision>
            <origin rpy="0 0 0" xyz="0.042795 0.17 -0.37525" />
            <geometry>
                <mesh filename="package://two_arm_description/meshes/bearing_v1_2.stl" scale="0.001 0.001 0.001" />
            </geometry>
        </collision>
    </link>
    <link name="joint_pivot_seat_v1_2">
        <inertial>
            <origin rpy="0 0 0" xyz="0.010686949814438351 -1.4002965453840943e-12 -7.16093850883226e-15" />
            <mass value="0.014233239752431062" />
            <inertia ixx="2.2e-05" ixy="0.0" ixz="-0.0" iyy="1.2e-05" iyz="9e-06" izz="1.6e-05" />
        </inertial>
        <visual>
            <origin rpy="0 0 0" xyz="0.022795 0.17 -0.37525" />
            <geometry>
                <mesh filename="package://two_arm_description/meshes/joint_pivot_seat_v1_2.stl" scale="1 1 1" />
            </geometry>
            <material name="silver" />
        </visual>
        <collision>
            <origin rpy="0 0 0" xyz="0.022795 0.17 -0.37525" />
            <geometry>
                <mesh filename="package://two_arm_description/meshes/joint_pivot_seat_v1_2.stl" scale="0.001 0.001 0.001" />
            </geometry>
        </collision>
    </link>
    <link name="s_s_link_v1_1">
        <inertial>
            <origin rpy="0 0 0" xyz="0.010821385526843454 0.0026874131383245736 -0.004673581940137617" />
            <mass value="0.001474300888156925" />
            <inertia ixx="0.0" ixy="0.0" ixz="0.0" iyy="0.0" iyz="0.0" izz="0.0" />
        </inertial>
        <visual>
            <origin rpy="0 0 0" xyz="-0.036783 0.163514 -0.386333" />
            <geometry>
                <mesh filename="package://two_arm_description/meshes/s_s_link_v1_1.stl" scale="1 1 1" />
            </geometry>
            <material name="silver" />
        </visual>
        <collision>
            <origin rpy="0 0 0" xyz="-0.036783 0.163514 -0.386333" />
            <geometry>
                <mesh filename="package://two_arm_description/meshes/s_s_link_v1_1.stl" scale="0.001 0.001 0.001" />
            </geometry>
        </collision>
    </link>
    <link name="motorwithROUE_v4_6">
        <inertial>
            <origin rpy="0 0 0" xyz="0.015436454184252206 0.019518494660792307 -0.019807329501377535" />
            <mass value="0.08480439041253407" />
            <inertia ixx="2.3e-05" ixy="2e-06" ixz="4e-06" iyy="3.5e-05" iyz="4e-06" izz="3.7e-05" />
        </inertial>
        <visual>
            <origin rpy="0 0 0" xyz="-0.015305 0.206672 -0.403841" />
            <geometry>
                <mesh filename="package://two_arm_description/meshes/motorwithROUE_v4_6.stl" scale="1 1 1" />
            </geometry>
            <material name="silver" />
        </visual>
        <collision>
            <origin rpy="0 0 0" xyz="-0.015305 0.206672 -0.403841" />
            <geometry>
                <mesh filename="package://two_arm_description/meshes/motorwithROUE_v4_6.stl" scale="0.001 0.001 0.001" />
            </geometry>
        </collision>
    </link>
    <link name="uparm1_v1_2">
        <inertial>
            <origin rpy="0 0 0" xyz="0.021063777564250617 0.016761609821162787 -0.016807633912565345" />
            <mass value="0.00664014891173441" />
            <inertia ixx="2e-06" ixy="-0.0" ixz="0.0" iyy="2e-06" iyz="1e-06" izz="3e-06" />
        </inertial>
        <visual>
            <origin rpy="0 0 0" xyz="-0.021316 0.134857 -0.380317" />
            <geometry>
                <mesh filename="package://two_arm_description/meshes/uparm1_v1_2.stl" scale="1 1 1" />
            </geometry>
            <material name="silver" />
        </visual>
        <collision>
            <origin rpy="0 0 0" xyz="-0.021316 0.134857 -0.380317" />
            <geometry>
                <mesh filename="package://two_arm_description/meshes/uparm1_v1_2.stl" scale="0.001 0.001 0.001" />
            </geometry>
        </collision>
    </link>
    <link name="uparm_out_v1_2">
        <inertial>
            <origin rpy="0 0 0" xyz="0.02083142276789944 0.003389970302133949 -0.050476207544237595" />
            <mass value="0.005528894316363056" />
            <inertia ixx="6e-06" ixy="-2e-06" ixz="2e-06" iyy="6e-06" iyz="1e-06" izz="5e-06" />
        </inertial>
        <visual>
            <origin rpy="0 0 0" xyz="-0.04213 0.088538 -0.344586" />
            <geometry>
                <mesh filename="package://two_arm_description/meshes/uparm_out_v1_2.stl" scale="1 1 1" />
            </geometry>
            <material name="silver" />
        </visual>
        <collision>
            <origin rpy="0 0 0" xyz="-0.04213 0.088538 -0.344586" />
            <geometry>
                <mesh filename="package://two_arm_description/meshes/uparm_out_v1_2.stl" scale="0.001 0.001 0.001" />
            </geometry>
        </collision>
    </link>
    <link name="uparm2_v1_2">
        <inertial>
            <origin rpy="0 0 0" xyz="0.007925748867128088 -0.022161638494264432 0.01573492556198336" />
            <mass value="0.004361377871447323" />
            <inertia ixx="1e-06" ixy="0.0" ixz="-0.0" iyy="1e-06" iyz="0.0" izz="1e-06" />
        </inertial>
        <visual>
            <origin rpy="0 0 0" xyz="-0.063476 0.076064 -0.317266" />
            <geometry>
                <mesh filename="package://two_arm_description/meshes/uparm2_v1_2.stl" scale="1 1 1" />
            </geometry>
            <material name="silver" />
        </visual>
        <collision>
            <origin rpy="0 0 0" xyz="-0.063476 0.076064 -0.317266" />
            <geometry>
                <mesh filename="package://two_arm_description/meshes/uparm2_v1_2.stl" scale="0.001 0.001 0.001" />
            </geometry>
        </collision>
    </link>
    <link name="uparm_in_v1_2">
        <inertial>
            <origin rpy="0 0 0" xyz="0.006449214155056199 -0.009966438444469886 -0.03578131088072084" />
            <mass value="0.0032836847073492706" />
            <inertia ixx="2e-06" ixy="-1e-06" ixz="0.0" iyy="2e-06" iyz="-0.0" izz="1e-06" />
        </inertial>
        <visual>
            <origin rpy="0 0 0" xyz="-0.077021 0.118992 -0.357943" />
            <geometry>
                <mesh filename="package://two_arm_description/meshes/uparm_in_v1_2.stl" scale="1 1 1" />
            </geometry>
            <material name="silver" />
        </visual>
        <collision>
            <origin rpy="0 0 0" xyz="-0.077021 0.118992 -0.357943" />
            <geometry>
                <mesh filename="package://two_arm_description/meshes/uparm_in_v1_2.stl" scale="0.001 0.001 0.001" />
            </geometry>
        </collision>
    </link>
    <link name="uparm3_v1_2">
        <inertial>
            <origin rpy="0 0 0" xyz="0.02388148550044794 0.0012607582664510703 -0.004569073902370213" />
            <mass value="0.002974291147078946" />
            <inertia ixx="1e-06" ixy="0.0" ixz="0.0" iyy="1e-06" iyz="1e-06" izz="1e-06" />
        </inertial>
        <visual>
            <origin rpy="0 0 0" xyz="-0.067856 0.073297 -0.312133" />
            <geometry>
                <mesh filename="package://two_arm_description/meshes/uparm3_v1_2.stl" scale="1 1 1" />
            </geometry>
            <material name="silver" />
        </visual>
        <collision>
            <origin rpy="0 0 0" xyz="-0.067856 0.073297 -0.312133" />
            <geometry>
                <mesh filename="package://two_arm_description/meshes/uparm3_v1_2.stl" scale="0.001 0.001 0.001" />
            </geometry>
        </collision>
    </link>
    <link name="motorwithROUE_v4_8">
        <inertial>
            <origin rpy="0 0 0" xyz="0.010089346348004749 -0.019915228060722955 -0.009320967152795456" />
            <mass value="0.08480439041253407" />
            <inertia ixx="3.2e-05" ixy="-7e-06" ixz="5e-06" iyy="3.3e-05" iyz="1e-06" izz="3e-05" />
        </inertial>
        <visual>
            <origin rpy="0 0 0" xyz="-0.093813 0.06019 -0.29803" />
            <geometry>
                <mesh filename="package://two_arm_description/meshes/motorwithROUE_v4_8.stl" scale="1 1 1" />
            </geometry>
            <material name="silver" />
        </visual>
        <collision>
            <origin rpy="0 0 0" xyz="-0.093813 0.06019 -0.29803" />
            <geometry>
                <mesh filename="package://two_arm_description/meshes/motorwithROUE_v4_8.stl" scale="0.001 0.001 0.001" />
            </geometry>
        </collision>
    </link>
    <link name="front_arm1_v1_2">
        <inertial>
            <origin rpy="0 0 0" xyz="0.018806165838819375 -0.004569093423120105 -0.03590062945024036" />
            <mass value="0.0207169446193885" />
            <inertia ixx="1.6e-05" ixy="-1e-06" ixz="-1e-06" iyy="1.4e-05" iyz="-3e-06" izz="1.2e-05" />
        </inertial>
        <visual>
            <origin rpy="0 0 0" xyz="-0.120522 0.055791 -0.300717" />
            <geometry>
                <mesh filename="package://two_arm_description/meshes/front_arm1_v1_2.stl" scale="1 1 1" />
            </geometry>
            <material name="silver" />
        </visual>
        <collision>
            <origin rpy="0 0 0" xyz="-0.120522 0.055791 -0.300717" />
            <geometry>
                <mesh filename="package://two_arm_description/meshes/front_arm1_v1_2.stl" scale="0.001 0.001 0.001" />
            </geometry>
        </collision>
    </link>
    <link name="motorwithROUE_v4_9">
        <inertial>
            <origin rpy="0 0 0" xyz="-0.00037832887626604306 0.020653187451674465 -0.013195693375551154" />
            <mass value="0.08480439041253407" />
            <inertia ixx="3.6e-05" ixy="-5e-06" ixz="-0.0" iyy="3.2e-05" iyz="-6e-06" izz="2.8e-05" />
        </inertial>
        <visual>
            <origin rpy="0 0 0" xyz="-0.162908 0.056618 -0.25488" />
            <geometry>
                <mesh filename="package://two_arm_description/meshes/motorwithROUE_v4_9.stl" scale="1 1 1" />
            </geometry>
            <material name="silver" />
        </visual>
        <collision>
            <origin rpy="0 0 0" xyz="-0.162908 0.056618 -0.25488" />
            <geometry>
                <mesh filename="package://two_arm_description/meshes/motorwithROUE_v4_9.stl" scale="0.001 0.001 0.001" />
            </geometry>
        </collision>
    </link>
    <link name="s_s_link2_v1_2">
        <inertial>
            <origin rpy="0 0 0" xyz="0.002536820352144087 0.0018345821303547387 -0.002185178256441017" />
            <mass value="0.0064776173686798945" />
            <inertia ixx="2e-06" ixy="0.0" ixz="-0.0" iyy="1e-06" iyz="-0.0" izz="2e-06" />
        </inertial>
        <visual>
            <origin rpy="0 0 0" xyz="-0.184472 0.013226 -0.238075" />
            <geometry>
                <mesh filename="package://two_arm_description/meshes/s_s_link2_v1_2.stl" scale="1 1 1" />
            </geometry>
            <material name="silver" />
        </visual>
        <collision>
            <origin rpy="0 0 0" xyz="-0.184472 0.013226 -0.238075" />
            <geometry>
                <mesh filename="package://two_arm_description/meshes/s_s_link2_v1_2.stl" scale="0.001 0.001 0.001" />
            </geometry>
        </collision>
    </link>
    <link name="motorwithROUE_v4_10">
        <inertial>
            <origin rpy="0 0 0" xyz="0.021944918741350822 -0.0004022013100095836 -0.03067500584684732" />
            <mass value="0.08480439041253407" />
            <inertia ixx="3.1e-05" ixy="-3e-06" ixz="7e-06" iyy="2.9e-05" iyz="4e-06" izz="3.4e-05" />
        </inertial>
        <visual>
            <origin rpy="0 0 0" xyz="-0.187472 -0.005841 -0.247432" />
            <geometry>
                <mesh filename="package://two_arm_description/meshes/motorwithROUE_v4_10.stl" scale="1 1 1" />
            </geometry>
            <material name="silver" />
        </visual>
        <collision>
            <origin rpy="0 0 0" xyz="-0.187472 -0.005841 -0.247432" />
            <geometry>
                <mesh filename="package://two_arm_description/meshes/motorwithROUE_v4_10.stl" scale="0.001 0.001 0.001" />
            </geometry>
        </collision>
    </link>
    <link name="MX-106T_v1_1">
        <inertial>
            <origin rpy="0 0 0" xyz="-0.02318853102604762 0.013503765278883417 -0.0008787078828319528" />
            <mass value="0.08336454126107713" />
            <inertia ixx="3.2e-05" ixy="0.0" ixz="-0.0" iyy="3.9e-05" iyz="-0.0" izz="2.1e-05" />
        </inertial>
        <visual>
            <origin rpy="0 0 0" xyz="0.049095 0.4445 -0.36" />
            <geometry>
                <mesh filename="package://two_arm_description/meshes/MX-106T_v1_1.stl" scale="1 1 1" />
            </geometry>
            <material name="silver" />
        </visual>
        <collision>
            <origin rpy="0 0 0" xyz="0.049095 0.4445 -0.36" />
            <geometry>
                <mesh filename="package://two_arm_description/meshes/MX-106T_v1_1.stl" scale="0.001 0.001 0.001" />
            </geometry>
        </collision>
    </link>
    <link name="MX-106T_v1_2">
        <inertial>
            <origin rpy="0 0 0" xyz="-0.022188531026159503 0.014503765279229974 -0.0008787078828318973" />
            <mass value="0.08336454126107713" />
            <inertia ixx="3.2e-05" ixy="0.0" ixz="-0.0" iyy="3.9e-05" iyz="-0.0" izz="2.1e-05" />
        </inertial>
        <visual>
            <origin rpy="0 0 0" xyz="0.049095 0.1845 -0.36" />
            <geometry>
                <mesh filename="package://two_arm_description/meshes/MX-106T_v1_2.stl" scale="1 1 1" />
            </geometry>
            <material name="silver" />
        </visual>
        <collision>
            <origin rpy="0 0 0" xyz="0.049095 0.1845 -0.36" />
            <geometry>
                <mesh filename="package://two_arm_description/meshes/MX-106T_v1_2.stl" scale="0.001 0.001 0.001" />
            </geometry>
        </collision>
    </link>
    <link name="ROUE_MX106T_v1_4">
        <inertial>
            <origin rpy="0 0 0" xyz="0.00043455378056489816 0.0011368167139066687 0.001459329124618658" />
            <mass value="0.0014398491546385346" />
            <inertia ixx="0.0" ixy="0.0" ixz="0.0" iyy="0.0" iyz="0.0" izz="0.0" />
        </inertial>
        <visual>
            <origin rpy="0 0 0" xyz="-0.02063 0.136652 -0.378013" />
            <geometry>
                <mesh filename="package://two_arm_description/meshes/ROUE_MX106T_v1_4.stl" scale="1 1 1" />
            </geometry>
            <material name="silver" />
        </visual>
        <collision>
            <origin rpy="0 0 0" xyz="-0.02063 0.136652 -0.378013" />
            <geometry>
                <mesh filename="package://two_arm_description/meshes/ROUE_MX106T_v1_4.stl" scale="0.001 0.001 0.001" />
            </geometry>
        </collision>
    </link>
    <link name="motorwithROUE_v4_7">
        <inertial>
            <origin rpy="0 0 0" xyz="-0.006026076068243628 0.0036293741743024244 -0.023476034810204605" />
            <mass value="0.08480439041253407" />
            <inertia ixx="2.3e-05" ixy="1e-06" ixz="1e-06" iyy="3.7e-05" iyz="-4e-06" izz="3.5e-05" />
        </inertial>
        <visual>
            <origin rpy="0 0 0" xyz="-0.036783 0.156417 -0.3808" />
            <geometry>
                <mesh filename="package://two_arm_description/meshes/motorwithROUE_v4_7.stl" scale="1 1 1" />
            </geometry>
            <material name="silver" />
        </visual>
        <collision>
            <origin rpy="0 0 0" xyz="-0.036783 0.156417 -0.3808" />
            <geometry>
                <mesh filename="package://two_arm_description/meshes/motorwithROUE_v4_7.stl" scale="0.001 0.001 0.001" />
            </geometry>
        </collision>
    </link>
    <link name="front_arm2_v1_1">
        <inertial>
            <origin rpy="0 0 0" xyz="0.0467672799355075 -0.00970848961051718 0.0006791287663466539" />
            <mass value="0.02426619851660452" />
            <inertia ixx="1.4e-05" ixy="-3e-06" ixz="-7e-06" iyy="2.9e-05" iyz="-2e-06" izz="2.5e-05" />
        </inertial>
        <visual>
            <origin rpy="0 0 0" xyz="-0.183312 0.623827 -0.200241" />
            <geometry>
                <mesh filename="package://two_arm_description/meshes/front_arm2_v1_1.stl" scale="1 1 1" />
            </geometry>
            <material name="silver" />
        </visual>
        <collision>
            <origin rpy="0 0 0" xyz="-0.183312 0.623827 -0.200241" />
            <geometry>
                <mesh filename="package://two_arm_description/meshes/front_arm2_v1_1.stl" scale="0.001 0.001 0.001" />
            </geometry>
        </collision>
    </link>
    <link name="front_arm2_v1_2">
        <inertial>
            <origin rpy="0 0 0" xyz="0.03787772098687031 -0.008283363199286273 -0.027902756431825326" />
            <mass value="0.02426619851660452" />
            <inertia ixx="2.2e-05" ixy="8e-06" ixz="5e-06" iyy="2e-05" iyz="-5e-06" izz="2.6e-05" />
        </inertial>
        <visual>
            <origin rpy="0 0 0" xyz="-0.207831 -0.037063 -0.21377" />
            <geometry>
                <mesh filename="package://two_arm_description/meshes/front_arm2_v1_2.stl" scale="1 1 1" />
            </geometry>
            <material name="silver" />
        </visual>
        <collision>
            <origin rpy="0 0 0" xyz="-0.207831 -0.037063 -0.21377" />
            <geometry>
                <mesh filename="package://two_arm_description/meshes/front_arm2_v1_2.stl" scale="0.001 0.001 0.001" />
            </geometry>
        </collision>
    </link>
    <joint name="dummy_joint" type="fixed">
        <origin rpy="0 0 0" xyz="0 0 0" />
        <parent link="world" />
        <child link="base_link" />
    </joint>
    <joint name="Rigid_3" type="fixed">
        <origin rpy="0 0 0" xyz="-0.002 0.0135 0.01525" />
        <parent link="MX-106T_v1_1" />
        <child link="ROUE_MX106T_v1_1" />
    </joint>
    <joint name="Rigid_4" type="fixed">
        <origin rpy="0 0 0" xyz="0.0053 0.0 0.0" />
        <parent link="ROUE_MX106T_v1_1" />
        <child link="bearing_v1_1" />
    </joint>
    <joint name="Revolute_5" type="continuous">
        <origin rpy="0 0 0" xyz="0.02 0.0 0.0" />
        <parent link="bearing_v1_1" />
        <child link="joint_pivot_seat_v1_1" />
        <axis xyz="1.0 0.0 -0.0" />
    </joint>
    <joint name="Rigid_10" type="fixed">
        <origin rpy="0 0 0" xyz="0.024964 -0.041188 0.016315" />
        <parent link="motorwithROUE_v4_1" />
        <child link="s_s_link_v1_2" />
    </joint>
    <joint name="Rigid_11" type="fixed">
        <origin rpy="0 0 0" xyz="0.0 -0.008394 0.003247" />
        <parent link="s_s_link_v1_2" />
        <child link="motorwithROUE_v4_2" />
    </joint>
    <joint name="Revolute_12" type="continuous">
        <origin rpy="0 0 0" xyz="0.0381 0.043368 -0.016778" />
        <parent link="joint_pivot_seat_v1_1" />
        <child link="motorwithROUE_v4_1" />
        <axis xyz="-0.0 0.932639 -0.36081" />
    </joint>
    <joint name="Revolute_13" type="continuous">
        <origin rpy="0 0 0" xyz="-0.043736 -0.023513 -0.01283" />
        <parent link="motorwithROUE_v4_2" />
        <child link="uparm1_v1_1" />
        <axis xyz="0.682649 0.263661 0.681523" />
    </joint>
    <joint name="Rigid_14" type="fixed">
        <origin rpy="0 0 0" xyz="-0.009058 -0.010119 0.021791" />
        <parent link="motorwithROUE_v4_2" />
        <child link="ROUE_MX106T_v1_2" />
    </joint>
    <joint name="Rigid_16" type="fixed">
        <origin rpy="0 0 0" xyz="0.032041 -0.049066 -0.020523" />
        <parent link="uparm1_v1_1" />
        <child link="uparm_out_v1_1" />
    </joint>
    <joint name="Rigid_18" type="fixed">
        <origin rpy="0 0 0" xyz="0.00627 -0.00349 -0.00328" />
        <parent link="uparm_out_v1_1" />
        <child link="uparm2_v1_1" />
    </joint>
    <joint name="Rigid_20" type="fixed">
        <origin rpy="0 0 0" xyz="0.009343 0.040194 -0.024908" />
        <parent link="uparm2_v1_1" />
        <child link="uparm_in_v1_1" />
    </joint>
    <joint name="Rigid_21" type="fixed">
        <origin rpy="0 0 0" xyz="0.030794 -0.014746 -0.012244" />
        <parent link="uparm_in_v1_1" />
        <child link="uparm3_v1_1" />
    </joint>
    <joint name="Rigid_22" type="fixed">
        <origin rpy="0 0 0" xyz="0.003362 -0.011054 -0.003419" />
        <parent link="uparm3_v1_1" />
        <child link="motorwithROUE_v4_3" />
    </joint>
    <joint name="Revolute_23" type="continuous">
        <origin rpy="0 0 0" xyz="0.017457 -0.036669 -0.019146" />
        <parent link="motorwithROUE_v4_3" />
        <child link="front_arm1_v1_1" />
        <axis xyz="0.682649 0.263661 0.681523" />
    </joint>
    <joint name="Rigid_24" type="fixed">
        <origin rpy="0 0 0" xyz="0.061259 -0.007918 -0.015745" />
        <parent link="front_arm1_v1_1" />
        <child link="motorwithROUE_v4_4" />
    </joint>
    <joint name="Revolute_26" type="continuous">
        <origin rpy="0 0 0" xyz="0.014282 -0.042962 -0.024096" />
        <parent link="motorwithROUE_v4_4" />
        <child link="s_s_link2_v1_1" />
        <axis xyz="-0.68808 0.545945 0.478006" />
    </joint>
    <joint name="Rigid_27" type="fixed">
        <origin rpy="0 0 0" xyz="-0.008457 0.000873 -0.019028" />
        <parent link="s_s_link2_v1_1" />
        <child link="motorwithROUE_v4_5" />
    </joint>
    <joint name="Rigid_28" type="fixed">
        <origin rpy="0 0 0" xyz="0.001 0.0145 0.01525" />
        <parent link="MX-106T_v1_2" />
        <child link="ROUE_MX106T_v1_3" />
    </joint>
    <joint name="Rigid_29" type="fixed">
        <origin rpy="0 0 0" xyz="0.0053 0.0 0.0" />
        <parent link="ROUE_MX106T_v1_3" />
        <child link="bearing_v1_2" />
    </joint>
    <joint name="Revolute_30" type="continuous">
        <origin rpy="0 0 0" xyz="0.02 0.0 0.0" />
        <parent link="bearing_v1_2" />
        <child link="joint_pivot_seat_v1_2" />
        <axis xyz="1.0 -0.0 -0.0" />
    </joint>
    <joint name="Rigid_31" type="fixed">
        <origin rpy="0 0 0" xyz="0.021478 0.043158 -0.017508" />
        <parent link="motorwithROUE_v4_6" />
        <child link="s_s_link_v1_1" />
    </joint>
    <joint name="Revolute_33" type="continuous">
        <origin rpy="0 0 0" xyz="0.0381 -0.036672 0.028591" />
        <parent link="joint_pivot_seat_v1_2" />
        <child link="motorwithROUE_v4_6" />
        <axis xyz="-0.0 -0.788637 0.614859" />
    </joint>
    <joint name="Revolute_35" type="continuous">
        <origin rpy="0 0 0" xyz="0.000686 0.001795 0.002304" />
        <parent link="ROUE_MX106T_v1_4" />
        <child link="uparm1_v1_2" />
        <axis xyz="0.228539 0.598586 0.767766" />
    </joint>
    <joint name="Rigid_36" type="fixed">
        <origin rpy="0 0 0" xyz="0.020814 0.046319 -0.035731" />
        <parent link="uparm1_v1_2" />
        <child link="uparm_out_v1_2" />
    </joint>
    <joint name="Rigid_37" type="fixed">
        <origin rpy="0 0 0" xyz="0.021346 0.012474 -0.02732" />
        <parent link="uparm_out_v1_2" />
        <child link="uparm2_v1_2" />
    </joint>
    <joint name="Rigid_38" type="fixed">
        <origin rpy="0 0 0" xyz="0.055705 0.015865 -0.022374" />
        <parent link="uparm1_v1_2" />
        <child link="uparm_in_v1_2" />
    </joint>
    <joint name="Rigid_39" type="fixed">
        <origin rpy="0 0 0" xyz="0.025726 0.015241 -0.032453" />
        <parent link="uparm_out_v1_2" />
        <child link="uparm3_v1_2" />
    </joint>
    <joint name="Rigid_40" type="fixed">
        <origin rpy="0 0 0" xyz="0.025957 0.013107 -0.014103" />
        <parent link="uparm3_v1_2" />
        <child link="motorwithROUE_v4_8" />
    </joint>
    <joint name="Revolute_41" type="continuous">
        <origin rpy="0 0 0" xyz="0.026709 0.004399 0.002687" />
        <parent link="motorwithROUE_v4_8" />
        <child link="front_arm1_v1_2" />
        <axis xyz="-0.228539 -0.598586 -0.767766" />
    </joint>
    <joint name="Rigid_42" type="fixed">
        <origin rpy="0 0 0" xyz="0.042386 -0.000827 -0.045837" />
        <parent link="front_arm1_v1_2" />
        <child link="motorwithROUE_v4_9" />
    </joint>
    <joint name="Revolute_43" type="continuous">
        <origin rpy="0 0 0" xyz="0.021564 0.043392 -0.016805" />
        <parent link="motorwithROUE_v4_9" />
        <child link="s_s_link2_v1_2" />
        <axis xyz="-0.664338 -0.480588 0.572442" />
    </joint>
    <joint name="Rigid_45" type="fixed">
        <origin rpy="0 0 0" xyz="0.003 0.019067 0.009357" />
        <parent link="s_s_link2_v1_2" />
        <child link="motorwithROUE_v4_10" />
    </joint>
    <joint name="Rigid_1" type="fixed">
        <origin rpy="0 0 0" xyz="-0.049095 -0.4445 0.36" />
        <parent link="base_link" />
        <child link="MX-106T_v1_1" />
    </joint>
    <joint name="Rigid_2" type="fixed">
        <origin rpy="0 0 0" xyz="-0.049095 -0.1845 0.36" />
        <parent link="base_link" />
        <child link="MX-106T_v1_2" />
    </joint>
    <joint name="Rigid_34" type="fixed">
        <origin rpy="0 0 0" xyz="-0.016153 0.019765 -0.002787" />
        <parent link="motorwithROUE_v4_7" />
        <child link="ROUE_MX106T_v1_4" />
    </joint>
    <joint name="Rigid_32" type="fixed">
        <origin rpy="0 0 0" xyz="0.0 0.007097 -0.005533" />
        <parent link="s_s_link_v1_1" />
        <child link="motorwithROUE_v4_7" />
    </joint>
    <joint name="Rigid_50" type="fixed">
        <origin rpy="0 0 0" xyz="0.023428 -0.038262 -0.022574" />
        <parent link="motorwithROUE_v4_5" />
        <child link="front_arm2_v1_1" />
    </joint>
    <joint name="Rigid_51" type="fixed">
        <origin rpy="0 0 0" xyz="0.020359 0.031222 -0.033662" />
        <parent link="motorwithROUE_v4_10" />
        <child link="front_arm2_v1_2" />
    </joint>
</robot>

